<?xml version="1.0"?>
<robot name="robot_model">
    <link name="base_link">
        <visual>
            <origin xyz="0.000 0.000 0.000" rpy=" 0.0000 0.000 0.000" />
            <geometry>
                <cylinder length="0.01" radius="0.2" />
            </geometry>
        </visual>
    </link>
    <joint name="joint_0" type="fixed">
        <!-- <movement type="weld" rigidity = "flexible"/> -->
        <parent link="base_link" />
        <child link="link_0_x" />
        <origin rpy="0 0 0" xyz="0 0 0" />
        <!-- <T_Parent_Joint xyz = "0.0000 0.0000 0.0000" rpy = "0.0000 0.0000 0.0000"/>
		<T_Child_Joint xyz = "0.0000 0.0000 0.0000" rpy = "0.0000 0.0000 0.0000"/> -->
    </joint>
    <!-- =================================================================================== -->
    <!-- | Link 0 and joint 1 | -->
    <!-- =================================================================================== -->
    <link name="link_0_x">
        <visual name="mesh_0_x">
            <origin xyz="0.000 0.000 0.000" rpy=" 0.0000 0.000 0.000" />
            <geometry>
                <mesh filename="package://robot_model/mesh/L0.obj" scale="1 1 1" />
            </geometry>
            <material name="l0_mtr">
                <texture filename="package://robot_model/mesh/texture/L0.png" />
            </material>
        </visual>
    </link>
    <joint name="joint_1_x" type="continuous">
        <!-- <movement type = "rotational" rigidity = "flexible"/> -->
        <parent link="link_0_x" />
        <child link="link_0_y" />
        <origin xyz="0.0000 0.0000 0.2500" rpy="0.0000 0.0000 0.0000" />
        <axis xyz="1 0 0" />
    </joint>
    <link name="link_0_y">
        <!-- dummy link does not need any attr. -->
        <!-- <visual name = "mesh_0_y">
			<origin xyz = "0.000 0.000 0.000" rpy = " 0.0000 0.000 0.000"/>
		</visual>  -->
        <visual>
            <origin xyz="0.000 0.000 0.000" rpy=" 0.0000 0.000 0.000" />
            <geometry>
                <cylinder length="0" radius="0" />
            </geometry>
        </visual>
    </link>
    <joint name="joint_1_y" type="continuous">
        <!-- <movement type = "rotational" rigidity = "flexible"/> -->
        <parent link="link_0_y" />
        <child link="link_0_z" />
        <origin xyz="0.0000 0.0000 0.0000" rpy="0.0000 0.0000 0.0000" />
        <axis xyz="0 1 0" />
    </joint>
    <link name="link_0_z">
        <!-- dummy link does not need any attr. -->
        <!-- <visual name = "mesh_0_z">
			<origin xyz = "0.000 0.000 0.000" rpy = " 0.0000 0.000 0.000"/>
		</visual>  -->
    </link>
    <joint name="joint_1_z" type="continuous">
        <!-- <movement type = "rotational" rigidity = "flexible"/> -->
        <parent link="link_0_z" />
        <child link="link_1_x" />
        <origin xyz="0.0000 0.0000 0.0000" rpy="0.0000 0.0000 0.0000" />
        <axis xyz="0 0 1" />
    </joint>
    <!-- =================================================================================== -->
    <!-- | Link 1 and joint 2 | -->
    <!-- =================================================================================== -->
    <link name="link_1_x">

        <inertial>
            <mass value="110.000" xyz=" 0.002646 0.018740 0.188026" />
            <inertia ixx="3.236370867" ixy="0.644464939" ixz="0.468238095" iyy="6.714710678" iyz="0.257842574" izz="5.649849463" />
        </inertial>

        <visual name="mesh_1_x">
            <origin xyz="0.000 0.000 0.000" rpy=" 0.0000 0.000 0.000" />
            <geometry>
                <mesh filename="package://robot_model/mesh/L1.obj" scale="1 1 1" />
            </geometry>
            <material name="l1_mtr">
                <texture filename="package://robot_model/mesh/texture/L1.png" />
            </material>
        </visual>
    </link>
    <joint name="joint_2_x" type="continuous">
        <!-- <movement type = "rotational" rigidity = "flexible"/> -->
        <parent link="link_1_x" />
        <child link="link_1_y" />
        <origin xyz="0.3500 0.0000 0.4250" rpy="0.0000 -1.5708 1.5708" />
        <axis xyz="1 0 0" />
    </joint>
    <link name="link_1_y">
        <!-- dummy link does not need any attr. -->
        <!-- <visual name = "mesh_1_y">
			<origin xyz = "0.000 0.000 0.000" rpy = " 0.0000 0.000 0.000"/>
		</visual>  -->
    </link>
    <joint name="joint_2_y" type="continuous">
        <!-- <movement type = "rotational" rigidity = "flexible"/> -->
        <parent link="link_1_y" />
        <child link="link_1_z" />
        <origin xyz="0.0000 0.0000 0.0000" rpy="0.0000 0.0000 0.0000" />
        <axis xyz="0 1 0" />
    </joint>
    <link name="link_1_z">
        <!-- dummy link does not need any attr. -->
        <!-- <visual name = "mesh_1_z">
			<origin xyz = "0.000 0.000 0.000" rpy = " 0.0000 0.000 0.000"/>
		</visual>  -->
    </link>
    <joint name="joint_2_z" type="continuous">
        <!-- <movement type = "rotational" rigidity = "flexible"/> -->
        <parent link="link_1_z" />
        <child link="link_2_x" />
        <origin xyz="0.0000 0.0000 0.0000" rpy="0.0000 0.0000 0.0000" />
        <axis xyz="0 0 1" />
    </joint>
    <!-- =================================================================================== -->
    <!-- | Link 2 and joint 3 | -->
    <!-- =================================================================================== -->
    <link name="link_2_x">

        <inertial>
            <mass value="239.748" xyz=" 0.427436 0.002950  0.236273" />
            <inertia ixx="4.30639745" ixy="0.165463221" ixz="4.341148242" iyy="40.01608253" iyz="0.022575289" izz="39.50583604" />
        </inertial>

        <visual name="mesh_2_x">
            <origin xyz="0.000 0.000 0.000" rpy=" 0.0000 0.000 0.000" />
            <geometry>
                <!-- <mesh filename = "L2.obj" scale = "1.0"/> -->
                <mesh filename="package://robot_model/mesh/L2.obj" />
            </geometry>
            <material name="l2_mtr">
                <texture filename="package://robot_model/mesh/texture/L2.png" />
            </material>
        </visual>
    </link>
    <joint name="joint_3_x" type="continuous">
        <!-- <movement type = "rotational" rigidity = "flexible"/> -->
        <parent link="link_2_x" />
        <child link="link_2_y" />
        <origin xyz="1.1500 0.0000 0.0000" rpy="0.0000 0.0000 -3.14159" />
        <axis xyz="1 0 0" />
    </joint>
    <link name="link_2_y">
        <!-- dummy link does not need any attr. -->
        <!-- <visual name = "mesh_2_y">
			<origin xyz = "0.000 0.000 0.000" rpy = " 0.0000 0.000 0.000"/>
		</visual>  -->
    </link>
    <joint name="joint_3_y" type="continuous">
        <!-- <movement type = "rotational" rigidity = "flexible"/> -->
        <parent link="link_2_y" />
        <child link="link_2_z" />
        <origin xyz="0.0000 0.0000 0.0000" rpy="0.0000 0.0000 0.0000" />
        <axis xyz="0 1 0" />
    </joint>
    <link name="link_2_z">
        <!-- dummy link does not need any attr. -->
        <!-- <visual name = "mesh_2_z">
			<origin xyz = "0.000 0.000 0.000" rpy = " 0.0000 0.000 0.000"/>
		</visual>  -->
    </link>
    <joint name="joint_3_z" type="continuous">
        <!-- <movement type = "rotational" rigidity = "flexible"/> -->
        <parent link="link_2_z" />
        <child link="link_3_x" />
        <origin xyz="0.0000 0.0000 0.0000" rpy="0.0000 0.0000 0.0000" />
        <axis xyz="0 0 1" />
    </joint>
    <!-- =================================================================================== -->
    <!-- | Link 3 and joint 4 | -->
    <!-- =================================================================================== -->
    <link name="link_3_x">

        <inertial>
            <mass value="164.006" xyz=" 0.023521 0.157165  0.000000" />
            <inertia ixx="16.43037097" ixy="0.336896677" ixz="0.018073572" iyy="2.381578838" iyz="0.191901642" izz="16.17115993" />
        </inertial>

        <visual name="mesh_3_z">
            <origin xyz="0.000 0.000 0.000" rpy=" 0.0000 0.000 0.000" />
            <geometry>
                <!-- <mesh filename = "L3.obj" scale = "1.0"/> -->
                <mesh filename="package://robot_model/mesh/L3.obj" />
            </geometry>
            <material name="l3_mtr">
                <texture filename="package://robot_model/mesh/texture/L3.png" />
            </material>
        </visual>
    </link>
    <joint name="joint_4_x" type="continuous">
        <!-- <movement type = "rotational" rigidity = "flexible"/> -->
        <parent link="link_3_x" />
        <child link="link_3_y" />
        <origin xyz="0.0410 0.7545 0.0000" rpy="-1.5708 0.0000 0.0000" />
        <axis xyz="1 0 0" />
    </joint>
    <link name="link_3_y">
        <!-- dummy link does not need any attr. -->
        <!-- <visual name = "mesh_3_y">
			<origin xyz = "0.000 0.000 0.000" rpy = " 0.0000 0.000 0.000"/>
		</visual>  -->
    </link>
    <joint name="joint_4_y" type="continuous">
        <!-- <movement type = "rotational" rigidity = "flexible"/> -->
        <parent link="link_3_y" />
        <child link="link_3_z" />
        <origin xyz="0.0000 0.0000 0.0000" rpy="0.0000 0.0000 0.0000" />
        <axis xyz="0 1 0" />
    </joint>
    <link name="link_3_z">
        <!-- dummy link does not need any attr. -->
        <!-- <visual name = "mesh_3_z">
			<origin xyz = "0.000 0.000 0.000" rpy = " 0.0000 0.000 0.000"/>
		</visual>  -->
    </link>
    <joint name="joint_4_z" type="continuous">
        <!-- <movement type = "rotational" rigidity = "flexible"/> -->
        <parent link="link_3_z" />
        <child link="link_4_x" />
        <origin xyz="0.0000 0.0000 0.0000" rpy="0.0000 0.0000 0.0000" />
        <axis xyz="0 0 1" />
    </joint>
    <!-- =================================================================================== -->
    <!-- | Link 4 and joint 5 | -->
    <!-- =================================================================================== -->
    <link name="link_4_x">

        <inertial>
            <mass value=" 39.746" xyz=" 0.000000 0.001354 0.223432" />
            <inertia ixx="0.419700279" ixy="0" ixz="0" iyy="0.425200882" iyz="0.009137089" izz="0.097243405" />
        </inertial>

        <visual name="mesh_4_x">
            <origin xyz="0.000 0.000 0.000" rpy=" 0.0000 0.000 0.000" />
            <geometry>
                <!-- <mesh filename = "L4.obj" scale = "1.0"/> -->
                <mesh filename="package://robot_model/mesh/L4.obj" />
            </geometry>
            <material name="l4_mtr">
                <texture filename="package://robot_model/mesh/texture/L4.png" />
            </material>
        </visual>
    </link>
    <joint name="joint_5_x" type="continuous">
        <!-- <movement type = "rotational" rigidity = "flexible"/> -->
        <parent link="link_4_x" />
        <child link="link_4_y" />
        <origin xyz="0.0000 0.0000 0.245500" rpy="1.5708 0.0000 0.0000" />
        <axis xyz="1 0 0" />
    </joint>
    <link name="link_4_y">
        <!-- dummy link does not need any attr. -->
        <!-- <visual name = "mesh_4_y">
			<origin xyz = "0.000 0.000 0.000" rpy = " 0.0000 0.000 0.000"/>
		</visual>  -->
    </link>
    <joint name="joint_5_y" type="continuous">
        <!-- <movement type = "rotational" rigidity = "flexible"/> -->
        <parent link="link_4_y" />
        <child link="link_4_z" />
        <origin xyz="0.0000 0.0000 0.0000" rpy="0.0000 0.0000 0.0000" />
        <axis xyz="0 1 0" />
    </joint>
    <link name="link_4_z">
        <!-- dummy link does not need any attr. -->
        <!-- <visual name = "mesh_4_z">
			<origin xyz = "0.000 0.000 0.000" rpy = " 0.0000 0.000 0.000"/>
		</visual>  -->
    </link>
    <joint name="joint_5_z" type="continuous">
        <!-- <movement type = "rotational" rigidity = "flexible"/> -->
        <parent link="link_4_z" />
        <child link="link_5_x" />
        <origin xyz="0.0000 0.0000 0.0000" rpy="0.0000 0.0000 0.0000" />
        <axis xyz="0 0 1" />
    </joint>
    <!-- =================================================================================== -->
    <!-- | Link 5 and joint 6 | -->
    <!-- =================================================================================== -->
    <link name="link_5_x">

        <inertial>
            <mass value=" 28.510" xyz=" 0.000000 0.054123 -0.037621" />
            <inertia ixx="0.436341228" ixy="0.000008171" ixz="0.000000068" iyy="0.296286531" iyz="0.06785905" izz="0.294686677" />
        </inertial>

        <visual name="mesh_5_x">
            <origin xyz="0.000 0.000 0.000" rpy=" 0.0000 0.000 0.000" />
            <geometry>
                <!-- <mesh filename = "L5.obj" scale = "1.0"/> -->
                <mesh filename="package://robot_model/mesh/L5.obj" />
            </geometry>
            <material name="l5_mtr">
                <texture filename="package://robot_model/mesh/texture/L5.png" />
            </material>
        </visual>
    </link>
    <joint name="joint_6_x" type="continuous">
        <!-- <movement type = "rotational" rigidity = "flexible"/> -->
        <parent link="link_5_x" />
        <child link="link_5_y" />
        <origin xyz="0.0000 0.2400 0.0000" rpy="-1.5708 0.0000 0.0000" />
        <axis xyz="1 0 0" />
    </joint>
    <link name="link_5_y">
        <!-- dummy link does not need any attr. -->
        <!-- <visual name = "mesh_5_y">
			<origin xyz = "0.000 0.000 0.000" rpy = " 0.0000 0.000 0.000"/>
		</visual>  -->
    </link>
    <joint name="joint_6_y" type="continuous">
        <!-- <movement type = "rotational" rigidity = "flexible"/> -->
        <parent link="link_5_y" />
        <child link="link_5_z" />
        <origin xyz="0.0000 0.0000 0.0000" rpy="0.0000 0.0000 0.0000" />
        <axis xyz="0 1 0" />
    </joint>
    <link name="link_5_z">
        <!-- dummy link does not need any attr. -->
        <!-- <visual name = "mesh_5_z">
			<origin xyz = "0.000 0.000 0.000" rpy = " 0.0000 0.000 0.000"/>
		</visual>  -->
    </link>
    <joint name="joint_6_z" type="continuous">
        <!-- <movement type = "rotational" rigidity = "flexible"/> -->
        <parent link="link_5_z" />
        <child link="link_6_x" />
        <origin xyz="0.0000 0.0000 0.0000" rpy="0.0000 0.0000 0.0000" />
        <axis xyz="0 0 1" />
    </joint>
    <!-- =================================================================================== -->
    <!-- | Link 6 | -->
    <!-- =================================================================================== -->
    <link name="link_6_x">

        <inertial>
            <mass value=" 78.622" xyz="-0.065895 0.000000  0.122766" />
            <inertia ixx="0.766497" ixy="0" ixz="0.01855" iyy="1.401573" iyz="0" izz="1.295152" />
        </inertial>

        <visual name="mesh_6">
            <origin xyz="0.000 0.000 0.000" rpy=" 0.0000 0.000 0.000" />
            <geometry>
                <!-- <mesh filename = "L6Spindle.obj" scale = "1.0"/> -->
                <mesh filename="package://robot_model/mesh/L6Spindle.obj" />
            </geometry>
            <material name="l6_mtr">
                <texture filename="package://robot_model/mesh/texture/L6Spindle.png" />
            </material>
        </visual>
    </link>
    <!-- <cosy name = "TCP">
		<parent link="link_6"/>
		<T_parent_cosy xyz = "0.1705 0.0000 0.1165" rpy = "0.0000 -1.5708 0.0000"/>
	</cosy> -->

    <transmission name="trans_joint_1_x">
        <type>transmission_interface/SimpleTransmission</type>
        <joint name="joint_1_x">
            <hardwareInterface>hardware_interface/EffortJointInterface</hardwareInterface>
        </joint>
        <actuator name="joint_1_x_motor">
            <hardwareInterface>hardware_interface/EffortJointInterface</hardwareInterface>
            <mechanicalReduction>1</mechanicalReduction>
        </actuator>
    </transmission>
    <transmission name="trans_joint_1_y">
        <type>transmission_interface/SimpleTransmission</type>
        <joint name="joint_1_y">
            <hardwareInterface>hardware_interface/EffortJointInterface</hardwareInterface>
        </joint>
        <actuator name="joint_1_y_motor">
            <hardwareInterface>hardware_interface/EffortJointInterface</hardwareInterface>
            <mechanicalReduction>1</mechanicalReduction>
        </actuator>
    </transmission>
    <transmission name="trans_joint_1_z">
        <type>transmission_interface/SimpleTransmission</type>
        <joint name="joint_1_z">
            <hardwareInterface>hardware_interface/EffortJointInterface</hardwareInterface>
        </joint>
        <actuator name="joint_1_z_motor">
            <hardwareInterface>hardware_interface/EffortJointInterface</hardwareInterface>
            <mechanicalReduction>1</mechanicalReduction>
        </actuator>
    </transmission>
    <transmission name="trans_joint_2_x">
        <type>transmission_interface/SimpleTransmission</type>
        <joint name="joint_2_x">
            <hardwareInterface>hardware_interface/EffortJointInterface</hardwareInterface>
        </joint>
        <actuator name="joint_2_x_motor">
            <hardwareInterface>hardware_interface/EffortJointInterface</hardwareInterface>
            <mechanicalReduction>1</mechanicalReduction>
        </actuator>
    </transmission>
    <transmission name="trans_joint_2_y">
        <type>transmission_interface/SimpleTransmission</type>
        <joint name="joint_2_y">
            <hardwareInterface>hardware_interface/EffortJointInterface</hardwareInterface>
        </joint>
        <actuator name="joint_2_y_motor">
            <hardwareInterface>hardware_interface/EffortJointInterface</hardwareInterface>
            <mechanicalReduction>1</mechanicalReduction>
        </actuator>
    </transmission>
    <transmission name="trans_joint_2_z">
        <type>transmission_interface/SimpleTransmission</type>
        <joint name="joint_2_z">
            <hardwareInterface>hardware_interface/EffortJointInterface</hardwareInterface>
        </joint>
        <actuator name="joint_2_z_motor">
            <hardwareInterface>hardware_interface/EffortJointInterface</hardwareInterface>
            <mechanicalReduction>1</mechanicalReduction>
        </actuator>
    </transmission>
    <transmission name="trans_joint_3_x">
        <type>transmission_interface/SimpleTransmission</type>
        <joint name="joint_3_x">
            <hardwareInterface>hardware_interface/EffortJointInterface</hardwareInterface>
        </joint>
        <actuator name="joint_3_x_motor">
            <hardwareInterface>hardware_interface/EffortJointInterface</hardwareInterface>
            <mechanicalReduction>1</mechanicalReduction>
        </actuator>
    </transmission>
    <transmission name="trans_joint_3_y">
        <type>transmission_interface/SimpleTransmission</type>
        <joint name="joint_3_y">
            <hardwareInterface>hardware_interface/EffortJointInterface</hardwareInterface>
        </joint>
        <actuator name="joint_3_y_motor">
            <hardwareInterface>hardware_interface/EffortJointInterface</hardwareInterface>
            <mechanicalReduction>1</mechanicalReduction>
        </actuator>
    </transmission>
    <transmission name="trans_joint_3_z">
        <type>transmission_interface/SimpleTransmission</type>
        <joint name="joint_3_z">
            <hardwareInterface>hardware_interface/EffortJointInterface</hardwareInterface>
        </joint>
        <actuator name="joint_3_z_motor">
            <hardwareInterface>hardware_interface/EffortJointInterface</hardwareInterface>
            <mechanicalReduction>1</mechanicalReduction>
        </actuator>
    </transmission>
    <transmission name="trans_joint_4_x">
        <type>transmission_interface/SimpleTransmission</type>
        <joint name="joint_4_x">
            <hardwareInterface>hardware_interface/EffortJointInterface</hardwareInterface>
        </joint>
        <actuator name="joint_4_x_motor">
            <hardwareInterface>hardware_interface/EffortJointInterface</hardwareInterface>
            <mechanicalReduction>1</mechanicalReduction>
        </actuator>
    </transmission>
    <transmission name="trans_joint_4_y">
        <type>transmission_interface/SimpleTransmission</type>
        <joint name="joint_4_y">
            <hardwareInterface>hardware_interface/EffortJointInterface</hardwareInterface>
        </joint>
        <actuator name="joint_4_y_motor">
            <hardwareInterface>hardware_interface/EffortJointInterface</hardwareInterface>
            <mechanicalReduction>1</mechanicalReduction>
        </actuator>
    </transmission>
    <transmission name="trans_joint_4_z">
        <type>transmission_interface/SimpleTransmission</type>
        <joint name="joint_4_z">
            <hardwareInterface>hardware_interface/EffortJointInterface</hardwareInterface>
        </joint>
        <actuator name="joint_4_z_motor">
            <hardwareInterface>hardware_interface/EffortJointInterface</hardwareInterface>
            <mechanicalReduction>1</mechanicalReduction>
        </actuator>
    </transmission>
    <transmission name="trans_joint_5_x">
        <type>transmission_interface/SimpleTransmission</type>
        <joint name="joint_5_x">
            <hardwareInterface>hardware_interface/EffortJointInterface</hardwareInterface>
        </joint>
        <actuator name="joint_5_x_motor">
            <hardwareInterface>hardware_interface/EffortJointInterface</hardwareInterface>
            <mechanicalReduction>1</mechanicalReduction>
        </actuator>
    </transmission>
    <transmission name="trans_joint_5_y">
        <type>transmission_interface/SimpleTransmission</type>
        <joint name="joint_5_y">
            <hardwareInterface>hardware_interface/EffortJointInterface</hardwareInterface>
        </joint>
        <actuator name="joint_5_y_motor">
            <hardwareInterface>hardware_interface/EffortJointInterface</hardwareInterface>
            <mechanicalReduction>1</mechanicalReduction>
        </actuator>
    </transmission>
    <transmission name="trans_joint_5_z">
        <type>transmission_interface/SimpleTransmission</type>
        <joint name="joint_5_z">
            <hardwareInterface>hardware_interface/EffortJointInterface</hardwareInterface>
        </joint>
        <actuator name="joint_5_z_motor">
            <hardwareInterface>hardware_interface/EffortJointInterface</hardwareInterface>
            <mechanicalReduction>1</mechanicalReduction>
        </actuator>
    </transmission>
    <transmission name="trans_joint_6_x">
        <type>transmission_interface/SimpleTransmission</type>
        <joint name="joint_6_x">
            <hardwareInterface>hardware_interface/EffortJointInterface</hardwareInterface>
        </joint>
        <actuator name="joint_6_x_motor">
            <hardwareInterface>hardware_interface/EffortJointInterface</hardwareInterface>
            <mechanicalReduction>1</mechanicalReduction>
        </actuator>
    </transmission>
    <transmission name="trans_joint_6_y">
        <type>transmission_interface/SimpleTransmission</type>
        <joint name="joint_6_y">
            <hardwareInterface>hardware_interface/EffortJointInterface</hardwareInterface>
        </joint>
        <actuator name="joint_6_y_motor">
            <hardwareInterface>hardware_interface/EffortJointInterface</hardwareInterface>
            <mechanicalReduction>1</mechanicalReduction>
        </actuator>
    </transmission>
    <transmission name="trans_joint_6_z">
        <type>transmission_interface/SimpleTransmission</type>
        <joint name="joint_6_z">
            <hardwareInterface>hardware_interface/EffortJointInterface</hardwareInterface>
        </joint>
        <actuator name="joint_6_z_motor">
            <hardwareInterface>hardware_interface/EffortJointInterface</hardwareInterface>
            <mechanicalReduction>1</mechanicalReduction>
        </actuator>
    </transmission>
    <gazebo>
        <plugin name="gazebo_ros_control" filename="libgazebo_ros_control.so">
            <robotNamespace>/</robotNamespace>
        </plugin>
    </gazebo>
</robot>